Workbook

Sheet 说明
A1: Intuitive Surgical (ISRG) 三年三情景估值模型
A2: 估值基准日：2026-10-15 ｜ 股价 $420.24（2026-10-14 收盘）｜ 货币：美元 ｜ 单位：百万美元（除每股、台数、手术量外）
A4: 一、模型结构
A5: 1. 历史数据：2021–2025 年报 + 2025/2026 上半年，全部取自 SEC 10-K / 10-Q / XBRL，蓝色为原始输入。
A6: 2. 假设：全局参数 + 乐观/基准/悲观三套驱动因子（黄色底 = 关键可调参数）。修改这里，其余各表自动重算。
A7: 3. 情景模型：驱动因子 → 收入（手术量 × 单台器械收入 + 装机 × 单台服务收入 + 系统收入）→ 利润 → GAAP / 非GAAP EPS → 2029 年目标价。
A8: 4. 估值汇总：三情景目标价、概率加权、折现到今天、买入区间、与一致预期对比。
A9: 5. 敏感性：退出 PE × 情景 EPS；手术量增速 × 单台器械收入变化；系统降价对 EPS 的影响。
A11: 二、颜色约定
A12: 蓝色字 = 硬编码输入（历史数据 / 假设）；黑色字 = 公式；绿色字 = 跨表引用；黄色底 = 关键情景参数。
A14: 三、核心口径
A15: • 单台器械收入 = I&A 收入 ÷ da Vinci 手术量（分母不含 Ion，因此该值包含 Ion 器械贡献；2025 年约 $1,909）。
... A27: 本模型仅供研究参考，不构成投资建议。

Sheet 估值汇总
A1: ISRG 三年三情景估值汇总
A2: 估值基准日 2026-10-15；目标价 = 2029E 非 GAAP EPS × 退出 PE；折现率与概率见「假设」表
A4: 指标 | B4: 乐观 | C4: 基准 | D4: 悲观 | E4: 概率加权
A5: 情景概率 | B5: =假设!$B$25 -> 0.25 | C5: =假设!$B$38 -> 0.5 | D5: =假设!$B$51 -> 0.25 | E5: =SUM(B5:D5) -> 1
A6: 2029E 收入（$mm） | B6: =情景模型!F14 -> 17391.241 | C6: =情景模型!F54 -> 15640.256 | D6: =情景模型!F94 -> 13376.482 | E6: =SUMPRODUCT($B$5:$D$5,B6:D6) -> 15512.059
A7: 收入复合增速 2025A–2029E | B7: =情景模型!B41 -> 0.14652211 | C7: =情景模型!B81 -> 0.11650521 | D7: =情景模型!B121 -> 0.073705731 | E7: =SUMPRODUCT($B$5:$D$5,B7:D7) -> 0.11330957
A8: 2029E GAAP 经营利润率 | B8: =情景模型!F20 -> 0.37524175 | C8: =情景模型!F60 -> 0.33716937 | D8: =情景模型!F100 -> 0.27726924 | E8: =SUMPRODUCT($B$5:$D$5,B8:D8) -> 0.33171243
A9: 2029E GAAP EPS（$） | B9: =情景模型!F27 -> 16.039445 | C9: =情景模型!F67 -> 13.036566 | D9: =情景模型!F107 -> 9.3217192 | E9: =SUMPRODUCT($B$5:$D$5,B9:D9) -> 12.858574
A10: 2029E 非 GAAP EPS（$） | B10: =情景模型!F31 -> 18.026558 | C10: =情景模型!F71 -> 15.137255 | D10: =情景模型!F111 -> 11.558902 | E10: =SUMPRODUCT($B$5:$D$5,B10:D10) -> 14.964993
A11: 非 GAAP EPS 复合增速 2026E–2029E | B11: =情景模型!B40 -> 0.17289273 | C11: =情景模型!B80 -> 0.11409611 | D11: =情景模型!B120 -> 0.027925986 | E11: =SUMPRODUCT($B$5:$D$5,B11:D11) -> 0.10725273
A12: 退出 PE（非 GAAP） | B12: =情景模型!B34 -> 40 | C12: =情景模型!B74 -> 30 | D12: =情景模型!B114 -> 22
A13: 2029E 目标价（$） | B13: =情景模型!B35 -> 721.06233 | C13: =情景模型!B75 -> 454.11766 | D13: =情景模型!B115 -> 254.29585 | E13: =SUMPRODUCT($B$5:$D$5,B13:D13) -> 470.89838
A14: 相对现价涨跌幅 | B14: =情景模型!B37 -> 0.7158346 | C14: =情景模型!B77 -> 0.08061503 | D14: =情景模型!B117 -> -0.39487947 | E14: =E13/假设!$B$4-1 -> 0.1205463
A15: 三年年化回报 | B15: =情景模型!B38 -> 0.1971773 | C15: =情景模型!B78 -> 0.026180288 | D15: =情景模型!B118 -> -0.15417478 | E15: =(E13/假设!$B$4)^(1/假设!$B$7)-1 -> 0.038667641
A16: 折现到今天的价值（$） | B16: =情景模型!B39 -> 541.7448 | C16: =情景模型!B79 -> 341.18532 | D16: =情景模型!B119 -> 191.05624 | E16: =SUMPRODUCT($B$5:$D$5,B16:D16) -> 353.79292
A18: 结论与价格区间
A19: 当前股价（$） | B19: =假设!$B$4 -> 420.24
A20: 概率加权 2029E 目标价（$） | B20: =E13 -> 470.89838
A21: 概率加权价值折现到今天（$） | B21: =E13/(1+假设!$B$6)^假设!$B$7 -> 353.79292
A22: 现价相对折现价值的溢价 /（折价） | B22: =假设!$B$4/B21-1 -> 0.18781348
A23: 买入区间上限（折现价值 × (1 − 安全边际)）（$） | B23: =B21*(1-假设!$B$8) -> 300.72398
A24: 分批建仓区间（$） | B24: =TEXT(B23,"$0")&" – "&TEXT(B21,"$0") -> $301 – $354
A25: 建议 | B25: =IF(假设!$B$4<=B23,"积极买入",IF(假设!$B$4<=B21,"分批建仓",IF(假设!$B$4<=E13,"观望 / 持有不加仓","高估 / 考虑减持"))) -> 观望 / 持有不加仓
A26: 现价要求的 2029E 非 GAAP EPS（按基准 PE、年化回报 = r）（$） | B26: =假设!$B$4*(1+假设!$B$6)^假设!$B$7/情景模型!B74 -> 18.644648
A27: 对应 2026E–2029E EPS 复合增速 | B27: =(B26/情景模型!C71)^(1/3)-1 -> 0.19424017
A28: 概率合计检查 | B28: =IF(ROUND(假设!$B$62,4)=1,"OK","概率合计不等于 100%") -> OK
A30: 模型 vs 一致预期（基准情景）
A31: 指标 | B31: 模型（基准） | C31: 一致预期 | D31: 差异
A32: 2026E 收入（$mm） | B32: =情景模型!C54 -> 11771.929 | C32: =假设!$B$15 -> 11760 | D32: =B32/C32-1 -> 0.0010143657
A33: 2026E 非 GAAP EPS（$） | B33: =情景模型!C71 -> 10.946598 | C33: =假设!$B$16 -> 10.8 | D33: =B33/C33-1 -> 0.013573883
A34: 2027E 非 GAAP EPS（$） | B34: =情景模型!D71 -> 11.922704 | C34: =假设!$B$17 -> 12.11 | D34: =B34/C34-1 -> -0.015466217
A35: 注：基准情景 2027E 低于一致预期，主要因为假设延寿计划使单台 I&A 收入下降 3%（一致预期可能尚未充分反映）。
A37: 情景描述
A38: 乐观 | B38: 美国手术增速回到 13%+；延寿计划影响 <2pct 且带动手术量；Ottava/Hugo 份额 <5%；dV5 降本推高毛利率；估值修复至 40x
A39: 基准 | B39: 手术增速逐年降至 11%；延寿计划使 2027 单台 I&A 收入 −3%；系统收入随换机放缓；估值向同业靠拢至 30x
A40: 悲观 | B40: 美国增速降至个位数；延寿 + 竞争降价使 2027 单台 I&A 收入 −6%；系统降价/份额流失；估值降至 22x（接近强生）

Sheet 历史数据
A1: ISRG 历史财务与经营数据（百万美元，另注明者除外）
A2: 来源：SEC 10-K（FY2021–FY2025）、10-Q（Q2 2026）、XBRL；蓝色 = 原始数据，黑色 = 计算
A4: 项目 | B4: 单位 | C4: 2021 | D4: 2022 | E4: 2023 | F4: 2024 | G4: 2025 | H4: H1 2025 | I4: H1 2026 | J4: 来源 / 备注
A5: 器械与耗材（I&A）收入 | B5: $mm | C5: 3101 | D5: 3518 | E5: 4276.6 | F5: 5079 | G5: 6018.9 | H5: 2841.8 | I5: 3421.3 | J5: 10-K 收入分项；2021–2022 取 StockAnalysis（与 10-K 一致）；H1 取 Q2 2026 新闻稿
A6: 系统收入 | B6: $mm | C6: 1693 | D6: 1680 | E6: 1679.7 | F6: 1966 | G6: 2473.7 | H6: 1097.4 | I6: 1335.7 | J6: 含经营租赁收入（2025 年 $874.3mm）
A7: 服务收入 | B7: $mm | C7: 916.2 | D7: 1024 | E7: 1167.8 | F7: 1307.1 | G7: 1572.1 | H7: 754.2 | I7: 906.1
A8: 总收入 | B8: $mm | C8: =C5+C6+C7 -> 5710.2 | D8: =D5+D6+D7 -> 6222 | E8: =E5+E6+E7 -> 7124.1 | F8: =F5+F6+F7 -> 8352.1 | G8: =G5+G6+G7 -> 10064.7 | H8: =H5+H6+H7 -> 4693.4 | I8: =I5+I6+I7 -> 5663.1 | J8: 计算：I&A + 系统 + 服务
A9: 毛利 | B9: $mm | C9: 3958.5 | D9: 4196 | E9: 4729.5 | F9: 5634.2 | G9: 6642.3 | H9: 3075.6 | I9: 3790.9 | J9: XBRL GrossProfit
A10: 销售、管理费用 | B10: $mm | C10: 1466.5 | D10: 1739.9 | E10: 1963.9 | F10: 2140 | G10: 2385 | H10: 1124.6 | I10: 1231.2 | J10: XBRL
A11: 研发费用 | B11: $mm | C11: 671 | D11: 879 | E11: 998.8 | F11: 1145.3 | G11: 1311.8 | H11: 629.5 | I11: 732.5 | J11: XBRL
A12: 运营费用合计 | B12: $mm | C12: =C10+C11 -> 2137.5 | D12: =D10+D11 -> 2618.9 | E12: =E10+E11 -> 2962.7 | F12: =F10+F11 -> 3285.3 | G12: =G10+G11 -> 3696.8 | H12: =H10+H11 -> 1754.1 | I12: =I10+I11 -> 1963.7 | J12: 计算：销售管理 + 研发
A13: 经营利润（GAAP） | B13: $mm | C13: =C9-C12 -> 1821 | D13: =D9-D12 -> 1577.1 | E13: =E9-E12 -> 1766.8 | F13: =F9-F12 -> 2348.9 | G13: =G9-G12 -> 2945.5 | H13: =H9-H12 -> 1321.5 | I13: =I9-I12 -> 1827.2 | J13: 计算：毛利 − 运营费用（2022 年 XBRL 经营利润 1,577.1，差额为其他经营项目）
A14: 利息及其他收入 | B14: $mm | C14: 69.3 | D14: 29.7 | E14: 192.1 | F14: 324.9 | G14: 365.9 | H14: 179.1 | I14: 167.8 | J14: XBRL NonoperatingIncomeExpense
A15: 税前利润 | B15: $mm | C15: 1890.3 | D15: 1606.8 | E15: 1958.9 | F15: 2673.8 | G15: 3311.4 | H15: 1500.6 | I15: 1995 | J15: XBRL
A16: 所得税 | B16: $mm | C16: 162.2 | D16: 262.4 | E16: 141.6 | F16: 336.3 | G16: 434.8 | H16: 132.7 | I16: 345.8 | J16: XBRL
A17: 少数股东损益 | B17: $mm | C17: 23.5 | D17: 22.1 | E17: 19.3 | F17: 14.9 | G17: 20.6 | H17: 11.1 | I17: 9.6 | J17: XBRL；复星合资公司
A18: GAAP 归母净利润 | B18: $mm | C18: 1704.6 | D18: 1322.3 | E18: 1798 | F18: 2322.6 | G18: 2856 | H18: 1356.8 | I18: 1639.6 | J18: XBRL / 新闻稿
A19: 稀释加权股本 | B19: 百万股 | C19: 365.8 | D19: 362 | E19: 357.4 | F19: 362 | G19: 362.7 | H19: 364.4 | I19: 358.5 | J19: XBRL
A20: GAAP 稀释 EPS | B20: $ | C20: 4.66 | D20: 3.65 | E20: 5.03 | F20: 6.42 | G20: 7.87 | H20: 3.72 | I20: 4.57 | J20: 公司披露值
A21: 非 GAAP 稀释 EPS | B21: $ | G21: 8.93 | H21: 4 | I21: 5.31 | J21: 2025：StockAnalysis；H1：Q2 2026 新闻稿调节表
A22: 股权激励费用（SBC） | B22: $mm | C22: 449.2 | D22: 513.2 | E22: 592.8 | F22: 676.8 | G22: 788.2 | H22: 381.4 | I22: 419.4 | J22: 现金流量表
A23: 经营现金流 | B23: $mm | C23: 2089.4 | D23: 1490.8 | E23: 1813.8 | F23: 2415 | G23: 3030.5 | H23: 1297 | I23: 1972.9
A24: 资本开支 | B24: $mm | C24: 339.5 | D24: 532.4 | E24: 1064.2 | F24: 1111.2 | G24: 539.8 | H24: 271.9 | I24: 215.9 | J24: XBRL PaymentsToAcquireProductiveAssets
A25: 自由现金流 | B25: $mm | C25: =C23-C24 -> 1749.9 | D25: =D23-D24 -> 958.4 | E25: =E23-E24 -> 749.6 | F25: =F23-F24 -> 1303.8 | G25: =G23-G24 -> 2490.7 | H25: =H23-H24 -> 1025.1 | I25: =I23-I24 -> 1757 | J25: 计算：经营现金流 − 资本开支
A26: da Vinci 手术量 | B26: 千台 | C26: 1594 | D26: 1875 | E26: 2286 | F26: 2683 | G26: 3153 | H26: 1507 | I26: 1737 | J26: 10-K / 10-Q
A27: da Vinci 装机量（期末） | B27: 台 | C27: 6730 | D27: 7544 | E27: 8606 | F27: 9902 | G27: 11106 | H27: 10488 | I27: 11710 | J27: 2020 年末 5,989 台；H1 列为 6 月 30 日
A28: da Vinci 投放量 | B28: 台 | C28: 1347 | D28: 1264 | E28: 1370 | F28: 1526 | G28: 1721 | H28: 762 | I28: 899
A29: 其中：换机投放 | B29: 台 | C29: 510 | D29: 345 | E29: 240 | F29: 150 | G29: 437 | H29: 150 | I29: 263
A31: 派生指标（公式）
A32: 收入增速 | C32: =C8/4358.4-1 -> 0.31015969 | D32: =IF(C8=0,"",D8/C8-1) -> 0.089629085 | E32: =IF(D8=0,"",E8/D8-1) -> 0.14498554 | F32: =IF(E8=0,"",F8/E8-1) -> 0.17237265 | G32: =IF(F8=0,"",G8/F8-1) -> 0.20505023 | I32: =IF(H8=0,"",I8/H8-1) -> 0.20660928 | J32: 2021 增速基于 2020 年收入 $4,358.4mm；手术量基于 2020 年 1,243 千台；装机基于 2020 年末 5,989 台
A33: 毛利率 | C33: =C9/C8 -> 0.69323316 | D33: =D9/D8 -> 0.67438123 | E33: =E9/E8 -> 0.66387333 | F33: =F9/F8 -> 0.67458483 | G33: =G9/G8 -> 0.65996006 | H33: =H9/H8 -> 0.65530319 | I33: =I9/I8 -> 0.66940368
A34: 经营利润率 | C34: =C13/C8 -> 0.31890302 | D34: =D13/D8 -> 0.25347155 | E34: =E13/E8 -> 0.24800326 | F34: =F13/F8 -> 0.28123466 | G34: =G13/G8 -> 0.29265651 | H34: =H13/H8 -> 0.2815656 | I34: =I13/I8 -> 0.32265014
A35: 净利率 | C35: =C18/C8 -> 0.29851844 | D35: =D18/D8 -> 0.21252009 | E35: =E18/E8 -> 0.25238276 | F35: =F18/F8 -> 0.27808575 | G35: =G18/G8 -> 0.28376405 | H35: =H18/H8 -> 0.2890868 | I35: =I18/I8 -> 0.28952341
A36: 有效税率 | C36: =C16/C15 -> 0.085806486 | D36: =D16/D15 -> 0.16330595 | E36: =E16/E15 -> 0.072285466 | F36: =F16/F15 -> 0.12577605 | G36: =G16/G15 -> 0.13130398 | H36: =H16/H15 -> 0.088431294 | I36: =I16/I15 -> 0.17333333
A37: SBC 占收入 | C37: =C22/C8 -> 0.078666246 | D37: =D22/D8 -> 0.082481517 | E37: =E22/E8 -> 0.083210511 | F37: =F22/F8 -> 0.081033513 | G37: =G22/G8 -> 0.078313313 | H37: =H22/H8 -> 0.08126305 | I37: =I22/I8 -> 0.074058378
A38: 手术量增速 | C38: =C26/1243-1 -> 0.28238134 | D38: =IF(C26=0,"",D26/C26-1) -> 0.17628607 | E38: =IF(D26=0,"",E26/D26-1) -> 0.2192 | F38: =IF(E26=0,"",F26/E26-1) -> 0.17366579 | G38: =IF(F26=0,"",G26/F26-1) -> 0.17517704 | I38: =IF(H26=0,"",I26/H26-1) -> 0.1526211
A39: 单台手术 I&A 收入（$，分母仅 da Vinci） | C39: =C5/C26*1000 -> 1945.4203 | D39: =D5/D26*1000 -> 1876.2667 | E39: =E5/E26*1000 -> 1870.7787 | F39: =F5/F26*1000 -> 1893.0302 | G39: =G5/G26*1000 -> 1908.9439 | H39: =H5/H26*1000 -> 1885.7332 | I39: =I5/I26*1000 -> 1969.6603
A40: 装机量增速 | C40: =C27/5989-1 -> 0.12372683 | D40: =IF(C27=0,"",D27/C27-1) -> 0.12095097 | E40: =IF(D27=0,"",E27/D27-1) -> 0.14077413 | F40: =IF(E27=0,"",F27/E27-1) -> 0.15059261 | G40: =IF(F27=0,"",G27/F27-1) -> 0.1215916
A41: 装机净增（台） | C41: =C27-5989 -> 741 | D41: =D27-C27 -> 814 | E41: =E27-D27 -> 1062 | F41: =F27-E27 -> 1296 | G41: =G27-F27 -> 1204

Sheet 假设
A1: 估值假设（蓝色 = 输入；黄色底 = 关键情景参数，可直接修改）
A3: 全局参数 | B3: 数值 | C3: 说明 / 来源
A4: 当前股价（$） | B4: 420.24 | C4: Yahoo / StockAnalysis，2026-10-14 收盘
A5: 总股本（百万股） | B5: 353.27804 | C5: 10-Q 封面，2026-07-16
A6: 资本成本 r（折现率） | B6: 0.1 | C6: 美元口径：10Y 美债 5.19% + ERP 约 4.8%，β=1.0
A7: 持有期（年） | B7: 3 | C7: 目标价对应 2029E EPS，约三年后
A8: 安全边际 | B8: 0.15 | C8: 买入区间 = 折现价值 ×（1 − 安全边际）
A9: GAAP 有效税率 | B9: 0.19 | C9: 2025 年 13.1%、H1 2026 17.3%（含股权激励超额税收优惠）；取 19% 偏保守
A10: 非 GAAP 税率 | B10: 0.225 | C10: 公司 2026 指引 22%–23%
A11: 少数股东损益（$mm/年） | B11: 20 | C11: 2025 年 $20.6mm
A12: 其他非 GAAP 调整（$mm/年，税前） | B12: 80 | C12: 无形资产摊销、收购相关等；H1 2026 约 $49mm
A13: 2026E 股权激励（$mm） | B13: 890 | C13: 公司 2026 指引 $880–900mm 中值
A14: 股权激励年增速（2027E 起） | B14: 0.08 | C14: 估计
A15: 一致预期：2026E 收入（$mm） | B15: 11760 | C15: StockAnalysis / S&P Global，2026-10-13
... A17: 一致预期：2027E 非 GAAP EPS（$） | B17: 12.11 | C17: 同上
A19: 利息及其他收入（$mm，三情景共用）
B20: 2026E | C20: 2027E | D20: 2028E | E20: 2029E | F20: 说明
A21: 利息及其他收入 | B21: 325 | C21: 340 | D21: 355 | E21: 370 | F21: 2026 指引 $315–335mm；此后随现金增加小幅上升（估计）
A23: 乐观情景：美国手术增速回到 13%+；延寿计划影响 <2pct 且带动手术量；Ottava/Hugo 份额 <5%；dV5 降本推高毛利率；估值修复至 40x
A24: 驱动因子 | B24: 2026E | C24: 2027E | D24: 2028E | E24: 2029E | F24: 说明
A25: 情景概率 | B25: 0.25 | F25: 单值（填在 2026E 列）
A26: 2029E 退出 PE（非 GAAP，倍） | B26: 40 | F26: 单值（填在 2026E 列）
A27: da Vinci 手术量增速 | B27: 0.15 | C27: 0.14 | D27: 0.13 | E27: 0.12 | F27: 2026 指引 13.5%–15.5%，接近中值
A28: 单台手术 I&A 收入变化 | B28: 0.03 | C28: -0.01 | D28: 0.01 | E28: 0.01 | F28: 2027 起含延寿计划与竞争降价影响（估计）
A29: da Vinci 装机量增速 | B29: 0.12 | C29: 0.12 | D29: 0.115 | E29: 0.11 | F29: 2025 年 12.2%，H1 2026 同比 11.7%
A30: 单台服务收入变化 | B30: 0.06 | C30: 0.05 | D30: 0.05 | E30: 0.05 | F30: dV5 服务合同更贵；竞争下续约折扣
A31: 系统收入增速 | B31: 0.17 | C31: 0.12 | D31: 0.12 | E31: 0.1 | F31: H1 2026 +21.7%；租赁占比上升、换机周期、降价
A32: GAAP 毛利率 | B32: 0.675 | C32: 0.685 | D32: 0.69 | E32: 0.695 | F32: H1 2026 为 66.9%；非 GAAP 指引 68%–69%
A33: 运营费用增速 | B33: 0.12 | C33: 0.11 | D33: 0.1 | E33: 0.1 | F33: 2026 非 GAAP 指引 +11%–13%
A34: 稀释股本变化 | B34: -0.014 | C34: -0.01 | D34: -0.01 | E34: -0.01 | F34: 回购净缩股；2026 年按 H1 实际约 −1.4%
A36: 基准情景：手术增速逐年降至 11%；延寿计划使 2027 单台 I&A 收入 −3%；系统收入随换机放缓；估值向同业靠拢至 30x
A37: 驱动因子 | B37: 2026E | C37: 2027E | D37: 2028E | E37: 2029E | F37: 说明
A38: 情景概率 | B38: 0.5 | F38: 单值（填在 2026E 列）
A39: 2029E 退出 PE（非 GAAP，倍） | B39: 30 | F39: 单值（填在 2026E 列）
A40: da Vinci 手术量增速 | B40: 0.145 | C40: 0.125 | D40: 0.12 | E40: 0.11 | F40: 2026 指引 13.5%–15.5%，接近中值
A41: 单台手术 I&A 收入变化 | B41: 0.025 | C41: -0.03 | D41: -0.01 | E41: 0 | F41: 2027 起含延寿计划与竞争降价影响（估计）
A42: da Vinci 装机量增速 | B42: 0.115 | C42: 0.11 | D42: 0.105 | E42: 0.1 | F42: 2025 年 12.2%，H1 2026 同比 11.7%
A43: 单台服务收入变化 | B43: 0.06 | C43: 0.03 | D43: 0.03 | E43: 0.03 | F43: dV5 服务合同更贵；竞争下续约折扣
A44: 系统收入增速 | B44: 0.15 | C44: 0.06 | D44: 0.06 | E44: 0.06 | F44: H1 2026 +21.7%；租赁占比上升、换机周期、降价
A45: GAAP 毛利率 | B45: 0.673 | C45: 0.67 | D45: 0.675 | E45: 0.68 | F45: H1 2026 为 66.9%；非 GAAP 指引 68%–69%
...

Sheet 情景模型
A1: 三情景驱动模型（百万美元；2025A 取自历史数据，2026E–2029E 由假设驱动）
A3: 乐观情景
A4: 项目 | B4: 2025A | C4: 2026E | D4: 2027E | E4: 2028E | F4: 2029E | G4: 备注
A5: da Vinci 手术量（千台） | B5: =历史数据!$G$26 -> 3153 | C5: =B5*(1+假设!B$27) -> 3625.95 | D5: =C5*(1+假设!C$27) -> 4133.583 | E5: =D5*(1+假设!D$27) -> 4670.9488 | F5: =E5*(1+假设!E$27) -> 5231.4626
A6: 手术量增速 | B6: =历史数据!G38 -> 0.17517704 | C6: =C5/B5-1 -> 0.15 | D6: =D5/C5-1 -> 0.14 | E6: =E5/D5-1 -> 0.13 | F6: =F5/E5-1 -> 0.12
A7: 单台手术 I&A 收入（$） | B7: =历史数据!$G$5/历史数据!$G$26*1000 -> 1908.9439 | C7: =B7*(1+假设!B$28) -> 1966.2122 | D7: =C7*(1+假设!C$28) -> 1946.5501 | E7: =D7*(1+假设!D$28) -> 1966.0156 | F7: =E7*(1+假设!E$28) -> 1985.6757 | G7: 分母仅 da Vinci，含 Ion 器械贡献
A8: I&A 收入 | B8: =历史数据!$G$5 -> 6018.9 | C8: =C5*C7/1000 -> 7129.3871 | D8: =D5*D7/1000 -> 8046.2262 | E8: =E5*E7/1000 -> 9183.158 | F8: =F5*F7/1000 -> 10387.988
A9: da Vinci 装机量（期末，台） | B9: =历史数据!$G$27 -> 11106 | C9: =B9*(1+假设!B$29) -> 12438.72 | D9: =C9*(1+假设!C$29) -> 13931.366 | E9: =D9*(1+假设!D$29) -> 15533.474 | F9: =E9*(1+假设!E$29) -> 17242.156
A10: 年均装机量（台） | B10: =(历史数据!$F$27+历史数据!$G$27)/2 -> 10504 | C10: =(B9+C9)/2 -> 11772.36 | D10: =(C9+D9)/2 -> 13185.043 | E10: =(D9+E9)/2 -> 14732.42 | F10: =(E9+F9)/2 -> 16387.815
A11: 单台服务收入（$千/年） | B11: =历史数据!$G$7/B10*1000 -> 149.66679 | C11: =B11*(1+假设!B$30) -> 158.6468 | D11: =C11*(1+假设!C$30) -> 166.57914 | E11: =D11*(1+假设!D$30) -> 174.9081 | F11: =E11*(1+假设!E$30) -> 183.6535 | G11: 含 Ion 服务贡献
A12: 服务收入 | B12: =历史数据!$G$7 -> 1572.1 | C12: =C10*C11/1000 -> 1867.6473 | D12: =D10*D11/1000 -> 2196.3532 | E12: =E10*E11/1000 -> 2576.8196 | F12: =F10*F11/1000 -> 3009.6796
A13: 系统收入 | B13: =历史数据!$G$6 -> 2473.7 | C13: =B13*(1+假设!B$31) -> 2894.229 | D13: =C13*(1+假设!C$31) -> 3241.5365 | E13: =D13*(1+假设!D$31) -> 3630.5209 | F13: =E13*(1+假设!E$31) -> 3993.5729
A14: 总收入 | B14: =历史数据!$G$8 -> 10064.7 | C14: =C8+C12+C13 -> 11891.263 | D14: =D8+D12+D13 -> 13484.116 | E14: =E8+E12+E13 -> 15390.498 | F14: =F8+F12+F13 -> 17391.241
A15: 收入增速 | B15: =历史数据!G32 -> 0.20505023 | C15: =C14/B14-1 -> 0.18148214 | D15: =D14/C14-1 -> 0.1339515 | E15: =E14/D14-1 -> 0.14137987 | F15: =F14/E14-1 -> 0.12999855
A16: GAAP 毛利率 | B16: =历史数据!$G$9/历史数据!$G$8 -> 0.65996006 | C16: =假设!B$32 -> 0.675 | D16: =假设!C$32 -> 0.685 | E16: =假设!D$32 -> 0.69 | F16: =假设!E$32 -> 0.695
A17: 毛利 | B17: =历史数据!$G$9 -> 6642.3 | C17: =C14*C16 -> 8026.6027 | D17: =D14*D16 -> 9236.6194 | E17: =E14*E16 -> 10619.444 | F17: =F14*F16 -> 12086.912
A18: 运营费用（销售管理 + 研发） | B18: =历史数据!$G$12 -> 3696.8 | C18: =B18*(1+假设!B$33) -> 4140.416 | D18: =C18*(1+假设!C$33) -> 4595.8618 | E18: =D18*(1+假设!D$33) -> 5055.4479 | F18: =E18*(1+假设!E$33) -> 5560.9927
A19: 经营利润（GAAP） | B19: =历史数据!$G$13 -> 2945.5 | C19: =C17-C18 -> 3886.1867 | D19: =D17-D18 -> 4640.7576 | E19: =E17-E18 -> 5563.996 | F19: =F17-F18 -> 6525.9196
A20: 经营利润率 | B20: =B19/B14 -> 0.29265651 | C20: =C19/C14 -> 0.32681025 | D20: =D19/D14 -> 0.34416477 | E20: =E19/E14 -> 0.36152149 | F20: =F19/F14 -> 0.37524175
A21: 利息及其他收入 | B21: =历史数据!$G$14 -> 365.9 | C21: =假设!B$21 -> 325 | D21: =假设!C$21 -> 340 | E21: =假设!D$21 -> 355 | F21: =假设!E$21 -> 370
A22: 税前利润 | B22: =历史数据!$G$15 -> 3311.4 | C22: =C19+C21 -> 4211.1867 | D22: =D19+D21 -> 4980.7576 | E22: =E19+E21 -> 5918.996 | F22: =F19+F21 -> 6895.9196
A23: 所得税（GAAP） | B23: =历史数据!$G$16 -> 434.8 | C23: =C22*假设!$B$9 -> 800.12548 | D23: =D22*假设!$B$9 -> 946.34395 | E23: =E22*假设!$B$9 -> 1124.6092 | F23: =F22*假设!$B$9 -> 1310.2247
A24: 少数股东损益 | B24: =历史数据!$G$17 -> 20.6 | C24: =假设!$B$11 -> 20 | D24: =假设!$B$11 -> 20 | E24: =假设!$B$11 -> 20 | F24: =假设!$B$11 -> 20
A25: GAAP 归母净利润 | B25: =历史数据!$G$18 -> 2856 | C25: =C22-C23-C24 -> 3391.0613 | D25: =D22-D23-D24 -> 4014.4137 | E25: =E22-E23-E24 -> 4774.3867 | F25: =F22-F23-F24 -> 5565.6949
A26: 稀释股本（百万股） | B26: =历史数据!$G$19 -> 362.7 | C26: =B26*(1+假设!B$34) -> 357.6222 | D26: =C26*(1+假设!C$34) -> 354.04598 | E26: =D26*(1+假设!D$34) -> 350.50552 | F26: =E26*(1+假设!E$34) -> 347.00046
A27: GAAP 稀释 EPS（$） | B27: =历史数据!$G$20 -> 7.87 | C27: =C25/C26 -> 9.4822448 | D27: =D25/D26 -> 11.338679 | E27: =E25/E26 -> 13.621431 | F27: =F25/F26 -> 16.039445
A28: 股权激励（SBC） | B28: =历史数据!$G$22 -> 788.2 | C28: =假设!$B$13 -> 890 | D28: =C28*(1+假设!$B$14) -> 961.2 | E28: =D28*(1+假设!$B$14) -> 1038.096 | F28: =E28*(1+假设!$B$14) -> 1121.1437
A29: 其他非 GAAP 调整（税前） | C29: =假设!$B$12 -> 80 | D29: =假设!$B$12 -> 80 | E29: =假设!$B$12 -> 80 | F29: =假设!$B$12 -> 80
A30: 非 GAAP 归母净利润 | C30: =(C22+C28+C29)*(1-假设!$B$10)-C24 -> 3995.4197 | D30: =(D22+D28+D29)*(1-假设!$B$10)-D24 -> 4647.0172 | E30: =(E22+E28+E29)*(1-假设!$B$10)-E24 -> 5433.7463 | F30: =(F22+F28+F29)*(1-假设!$B$10)-F24 -> 6255.2241 | G30: （税前 + SBC + 其他调整）×（1 − 非GAAP税率）− 少数股东
A31: 非 GAAP 稀释 EPS（$） | B31: =历史数据!$G$21 -> 8.93 | C31: =C30/C26 -> 11.17218 | D31: =D30/D26 -> 13.125462 | E31: =E30/E26 -> 15.502598 | F31: =F30/F26 -> 18.026558
A32: 非 GAAP EPS 增速 | C32: =IF(B31=0,"",C31/B31-1) -> 0.25108403 | D32: =IF(C31=0,"",D31/C31-1) -> 0.17483445 | E32: =IF(D31=0,"",E31/D31-1) -> 0.18110875 | F32: =IF(E31=0,"",F31/E31-1) -> 0.16280883
A33: 2029E 估值
A34: 退出 PE（非 GAAP） | B34: =假设!$B$26 -> 40
A35: 2029E 目标价（$） | B35: =F31*B34 -> 721.06233
A36: 对应 GAAP PE | B36: =B35/F27 -> 44.955566
A37: 相对现价涨跌幅 | B37: =B35/假设!$B$4-1 -> 0.7158346
A38: 三年年化回报 | B38: =(B35/假设!$B$4)^(1/假设!$B$7)-1 -> 0.1971773
A39: 折现到今天的价值（$） | B39: =B35/(1+假设!$B$6)^假设!$B$7 -> 541.7448
A40: 非 GAAP EPS 复合增速（2026E–2029E） | B40: =(F31/C31)^(1/3)-1 -> 0.17289273
A41: 收入复合增速（2025A–2029E） | B41: =(F14/B14)^(1/4)-1 -> 0.14652211
...

Sheet 敏感性
A1: 敏感性分析
A3: 表 1：2029E 目标价 = 2029E 非 GAAP EPS × 退出 PE（$）
A4: 退出 PE | B4: 乐观 | C4: 基准 | D4: 悲观 | E4: 基准折现到今天
A5: 2029E 非 GAAP EPS → | B5: =情景模型!F31 -> 18.026558 | C5: =情景模型!F71 -> 15.137255 | D5: =情景模型!F111 -> 11.558902
A6: 20 | B6: =B$5*$A6 -> 360.53117 | C6: =C$5*$A6 -> 302.74511 | D6: =D$5*$A6 -> 231.17805 | E6: =C6/(1+假设!$B$6)^假设!$B$7 -> 227.45688
A7: 22 | B7: =B$5*$A7 -> 396.58428 | C7: =C$5*$A7 -> 333.01962 | D7: =D$5*$A7 -> 254.29585 | E7: =C7/(1+假设!$B$6)^假设!$B$7 -> 250.20257
A8: 25 | B8: =B$5*$A8 -> 450.66396 | C8: =C$5*$A8 -> 378.43138 | D8: =D$5*$A8 -> 288.97256 | E8: =C8/(1+假设!$B$6)^假设!$B$7 -> 284.3211
A9: 28 | B9: =B$5*$A9 -> 504.74363 | C9: =C$5*$A9 -> 423.84315 | D9: =D$5*$A9 -> 323.64927 | E9: =C9/(1+假设!$B$6)^假设!$B$7 -> 318.43963
A10: 30 | B10: =B$5*$A10 -> 540.79675 | C10: =C$5*$A10 -> 454.11766 | D10: =D$5*$A10 -> 346.76707 | E10: =C10/(1+假设!$B$6)^假设!$B$7 -> 341.18532
A11: 32 | B11: =B$5*$A11 -> 576.84987 | C11: =C$5*$A11 -> 484.39217 | D11: =D$5*$A11 -> 369.88488 | E11: =C11/(1+假设!$B$6)^假设!$B$7 -> 363.93101
A12: 35 | B12: =B$5*$A12 -> 630.92954 | C12: =C$5*$A12 -> 529.80394 | D12: =D$5*$A12 -> 404.56158 | E12: =C12/(1+假设!$B$6)^假设!$B$7 -> 398.04954
A13: 38 | B13: =B$5*$A13 -> 685.00921 | C13: =C$5*$A13 -> 575.2157 | D13: =D$5*$A13 -> 439.23829 | E13: =C13/(1+假设!$B$6)^假设!$B$7 -> 432.16807
A14: 40 | B14: =B$5*$A14 -> 721.06233 | C14: =C$5*$A14 -> 605.49021 | D14: =D$5*$A14 -> 462.3561 | E14: =C14/(1+假设!$B$6)^假设!$B$7 -> 454.91376
A15: 45 | B15: =B$5*$A15 -> 811.19512 | C15: =C$5*$A15 -> 681.17649 | D15: =D$5*$A15 -> 520.15061 | E15: =C15/(1+假设!$B$6)^假设!$B$7 -> 511.77798
A18: 表 2：基准情景 2029E 目标价（$）——手术量复合增速（2025–2029）× 单台 I&A 收入累计变化（2025→2029）；其他项目沿用基准情景
A19: 基准退出 PE： | B19: =情景模型!B74 -> 30
A20: 手术量 CAGR | B20: −10% | C20: −5% | D20: 0% | E20: +5% | F20: +10%
A21: 单台 I&A 累计变化 → | B21: -0.1 | C21: -0.05 | D21: 0 | E21: 0.05 | F21: 0.1
A22: 0.08 | B22: =((((情景模型!$B$45*(1+$A22)^4*情景模型!$B$47*(1+B$21)/1000+情景模型!$F$52+情景模型!$F$53)*情景模型!$F$56-情景模型!$F$58+情景模型!$F$61)+情景模型!$F$68+情景模型!$F$69)*(1-假设!$B$10)-情景模型!$F$64)/情景模型!$F$66*$B$19 -> 358.21764 | C22: =((((情景模型!$B$45*(1+$A22)^4*情景模型!$B$47*(1+C$21)/1000+情景模型!$F$52+情景模型!$F$53)*情景模型!$F$56-情景模型!$F$58+情景模型!$F$61)+情景模型!$F$68+情景模型!$F$69)*(1-假设!$B$10)-情景模型!$F$64)/情景模型!$F$66*$B$19 -> 376.75955 | D22: =((((情景模型!$B$45*(1+$A22)^4*情景模型!$B$47*(1+D$21)/1000+情景模型!$F$52+情景模型!$F$53)*情景模型!$F$56-情景模型!$F$58+情景模型!$F$61)+情景模型!$F$68+情景模型!$F$69)*(1-假设!$B$10)-情景模型!$F$64)/情景模型!$F$66*$B$19 -> 395.30147 | E22: =((((情景模型!$B$45*(1+$A22)^4*情景模型!$B$47*(1+E$21)/1000+情景模型!$F$52+情景模型!$F$53)*情景模型!$F$56-情景模型!$F$58+情景模型!$F$61)+情景模型!$F$68+情景模型!$F$69)*(1-假设!$B$10)-情景模型!$F$64)/情景模型!$F$66*$B$19 -> 413.84338 | F22: =((((情景模型!$B$45*(1+$A22)^4*情景模型!$B$47*(1+F$21)/1000+情景模型!$F$52+情景模型!$F$53)*情景模型!$F$56-情景模型!$F$58+情景模型!$F$61)+情景模型!$F$68+情景模型!$F$69)*(1-假设!$B$10)-情景模型!$F$64)/情景模型!$F$66*$B$19 -> 432.38529
A23: 0.1 | B23: =((((情景模型!$B$45*(1+$A23)^4*情景模型!$B$47*(1+B$21)/1000+情景模型!$F$52+情景模型!$F$53)*情景模型!$F$56-情景模型!$F$58+情景模型!$F$61)+情景模型!$F$68+情景模型!$F$69)*(1-假设!$B$10)-情景模型!$F$64)/情景模型!$F$66*$B$19 -> 383.63545 | C23: =((((情景模型!$B$45*(1+$A23)^4*情景模型!$B$47*(1+C$21)/1000+情景模型!$F$52+情景模型!$F$53)*情景模型!$F$56-情景模型!$F$58+情景模型!$F$61)+情景模型!$F$68+情景模型!$F$69)*(1-假设!$B$10)-情景模型!$F$64)/情景模型!$F$66*$B$19 -> 403.58946 | D23: =((((情景模型!$B$45*(1+$A23)^4*情景模型!$B$47*(1+D$21)/1000+情景模型!$F$52+情景模型!$F$53)*情景模型!$F$56-情景模型!$F$58+情景模型!$F$61)+情景模型!$F$68+情景模型!$F$69)*(1-假设!$B$10)-情景模型!$F$64)/情景模型!$F$66*$B$19 -> 423.54347 | E23: =((((情景模型!$B$45*(1+$A23)^4*情景模型!$B$47*(1+E$21)/1000+情景模型!$F$52+情景模型!$F$53)*情景模型!$F$56-情景模型!$F$58+情景模型!$F$61)+情景模型!$F$68+情景模型!$F$69)*(1-假设!$B$10)-情景模型!$F$64)/情景模型!$F$66*$B$19 -> 443.49749 | F23: =((((情景模型!$B$45*(1+$A23)^4*情景模型!$B$47*(1+F$21)/1000+情景模型!$F$52+情景模型!$F$53)*情景模型!$F$56-情景模型!$F$58+情景模型!$F$61)+情景模型!$F$68+情景模型!$F$69)*(1-假设!$B$10)-情景模型!$F$64)/情景模型!$F$66*$B$19 -> 463.4515
A24: 0.12 | B24: =((((情景模型!$B$45*(1+$A24)^4*情景模型!$B$47*(1+B$21)/1000+情景模型!$F$52+情景模型!$F$53)*情景模型!$F$56-情景模型!$F$58+情景模型!$F$61)+情景模型!$F$68+情景模型!$F$69)*(1-假设!$B$10)-情景模型!$F$64)/情景模型!$F$66*$B$19 -> 410.47815 | C24: =((((情景模型!$B$45*(1+$A24)^4*情景模型!$B$47*(1+C$21)/1000+情景模型!$F$52+情景模型!$F$53)*情景模型!$F$56-情景模型!$F$58+情景模型!$F$61)+情景模型!$F$68+情景模型!$F$69)*(1-假设!$B$10)-情景模型!$F$64)/情景模型!$F$66*$B$19 -> 431.92342 | D24: =((((情景模型!$B$45*(1+$A24)^4*情景模型!$B$47*(1+D$21)/1000+情景模型!$F$52+情景模型!$F$53)*情景模型!$F$56-情景模型!$F$58+情景模型!$F$61)+情景模型!$F$68+情景模型!$F$69)*(1-假设!$B$10)-情景模型!$F$64)/情景模型!$F$66*$B$19 -> 453.36869 | E24: =((((情景模型!$B$45*(1+$A24)^4*情景模型!$B$47*(1+E$21)/1000+情景模型!$F$52+情景模型!$F$53)*情景模型!$F$56-情景模型!$F$58+情景模型!$F$61)+情景模型!$F$68+情景模型!$F$69)*(1-假设!$B$10)-情景模型!$F$64)/情景模型!$F$66*$B$19 -> 474.81397 | F24: =((((情景模型!$B$45*(1+$A24)^4*情景模型!$B$47*(1+F$21)/1000+情景模型!$F$52+情景模型!$F$53)*情景模型!$F$56-情景模型!$F$58+情景模型!$F$61)+情景模型!$F$68+情景模型!$F$69)*(1-假设!$B$10)-情景模型!$F$64)/情景模型!$F$66*$B$19 -> 496.25924
A25: 0.14 | B25: =((((情景模型!$B$45*(1+$A25)^4*情景模型!$B$47*(1+B$21)/1000+情景模型!$F$52+情景模型!$F$53)*情景模型!$F$56-情景模型!$F$58+情景模型!$F$61)+情景模型!$F$68+情景模型!$F$69)*(1-假设!$B$10)-情景模型!$F$64)/情景模型!$F$66*$B$19 -> 438.79802 | C25: =((((情景模型!$B$45*(1+$A25)^4*情景模型!$B$47*(1+C$21)/1000+情景模型!$F$52+情景模型!$F$53)*情景模型!$F$56-情景模型!$F$58+情景模型!$F$61)+情景模型!$F$68+情景模型!$F$69)*(1-假设!$B$10)-情景模型!$F$64)/情景模型!$F$66*$B$19 -> 461.81662 | D25: =((((情景模型!$B$45*(1+$A25)^4*情景模型!$B$47*(1+D$21)/1000+情景模型!$F$52+情景模型!$F$53)*情景模型!$F$56-情景模型!$F$58+情景模型!$F$61)+情景模型!$F$68+情景模型!$F$69)*(1-假设!$B$10)-情景模型!$F$64)/情景模型!$F$66*$B$19 -> 484.83522 | E25: =((((情景模型!$B$45*(1+$A25)^4*情景模型!$B$47*(1+E$21)/1000+情景模型!$F$52+情景模型!$F$53)*情景模型!$F$56-情景模型!$F$58+情景模型!$F$61)+情景模型!$F$68+情景模型!$F$69)*(1-假设!$B$10)-情景模型!$F$64)/情景模型!$F$66*$B$19 -> 507.85382 | F25: =((((情景模型!$B$45*(1+$A25)^4*情景模型!$B$47*(1+F$21)/1000+情景模型!$F$52+情景模型!$F$53)*情景模型!$F$56-情景模型!$F$58+情景模型!$F$61)+情景模型!$F$68+情景模型!$F$69)*(1-假设!$B$10)-情景模型!$F$64)/情景模型!$F$66*$B$19 -> 530.87243
A26: 0.16 | B26: =((((情景模型!$B$45*(1+$A26)^4*情景模型!$B$47*(1+B$21)/1000+情景模型!$F$52+情景模型!$F$53)*情景模型!$F$56-情景模型!$F$58+情景模型!$F$61)+情景模型!$F$68+情景模型!$F$69)*(1-假设!$B$10)-情景模型!$F$64)/情景模型!$F$66*$B$19 -> 468.6483 | C26: =((((情景模型!$B$45*(1+$A26)^4*情景模型!$B$47*(1+C$21)/1000+情景模型!$F$52+情景模型!$F$53)*情景模型!$F$56-情景模型!$F$58+情景模型!$F$61)+情景模型!$F$68+情景模型!$F$69)*(1-假设!$B$10)-情景模型!$F$64)/情景模型!$F$66*$B$19 -> 493.32525 | D26: =((((情景模型!$B$45*(1+$A26)^4*情景模型!$B$47*(1+D$21)/1000+情景模型!$F$52+情景模型!$F$53)*情景模型!$F$56-情景模型!$F$58+情景模型!$F$61)+情景模型!$F$68+情景模型!$F$69)*(1-假设!$B$10)-情景模型!$F$64)/情景模型!$F$66*$B$19 -> 518.0022 | E26: =((((情景模型!$B$45*(1+$A26)^4*情景模型!$B$47*(1+E$21)/1000+情景模型!$F$52+情景模型!$F$53)*情景模型!$F$56-情景模型!$F$58+情景模型!$F$61)+情景模型!$F$68+情景模型!$F$69)*(1-假设!$B$10)-情景模型!$F$64)/情景模型!$F$66*$B$19 -> 542.67915 | F26: =((((情景模型!$B$45*(1+$A26)^4*情景模型!$B$47*(1+F$21)/1000+情景模型!$F$52+情景模型!$F$53)*情景模型!$F$56-情景模型!$F$58+情景模型!$F$61)+情景模型!$F$68+情景模型!$F$69)*(1-假设!$B$10)-情景模型!$F$64)/情景模型!$F$66*$B$19 -> 567.3561
A28: 注：基准情景假设手术量 CAGR 约 12.5%、单台 I&A 累计变化约 −1.6%。
A30: 表 3：系统降价对基准情景 2029E 非 GAAP EPS 的影响（降价全部落到利润；未计降价带来的装机增量）
A31: 系统降价幅度 | B31: 收入损失（$mm） | C31: EPS 影响（$） | D31: EPS 影响（%） | E31: 2029E 目标价（$）
A32: 0 | B32: =情景模型!$F$53*A32 -> 0 | C32: =-B32*(1-假设!$B$10)/情景模型!$F$66 -> 0 | D32: =C32/情景模型!$F$71 -> 0 | E32: =(情景模型!$F$71+C32)*情景模型!$B$74 -> 454.11766
A33: 0.05 | B33: =情景模型!$F$53*A33 -> 169.40744 | C33: =-B33*(1-假设!$B$10)/情景模型!$F$66 -> -0.37607519 | D33: =C33/情景模型!$F$71 -> -0.024844345 | E33: =(情景模型!$F$71+C33)*情景模型!$B$74 -> 442.8354
A34: 0.1 | B34: =情景模型!$F$53*A34 -> 338.81487 | C34: =-B34*(1-假设!$B$10)/情景模型!$F$66 -> -0.75215038 | D34: =C34/情景模型!$F$71 -> -0.04968869 | E34: =(情景模型!$F$71+C34)*情景模型!$B$74 -> 431.55315
A35: 0.15 | B35: =情景模型!$F$53*A35 -> 508.22231 | C35: =-B35*(1-假设!$B$10)/情景模型!$F$66 -> -1.1282256 | D35: =C35/情景模型!$F$71 -> -0.074533034 | E35: =(情景模型!$F$71+C35)*情景模型!$B$74 -> 420.27089
A36: 0.2 | B36: =情景模型!$F$53*A36 -> 677.62974 | C36: =-B36*(1-假设!$B$10)/情景模型!$F$66 -> -1.5043008 | D36: =C36/情景模型!$F$71 -> -0.099377379 | E36: =(情景模型!$F$71+C36)*情景模型!$B$74 -> 408.98864
A38: 对比：单台 I&A 收入每下降 1%，2029E 收入减少约 1% × I&A 收入；见表 2 横向变化。
